<?xml version="1.0" encoding="utf-8"?>
<!-- This URDF was automatically created by SolidWorks to URDF Exporter! Originally created by Stephen Brawner (brawner@gmail.com) 
     Commit Version: 1.6.0-1-g15f4949  Build Version: 1.6.7594.29634
     For more information, please see http://wiki.ros.org/sw_urdf_exporter -->
<robot
  name="robot_simulation">
  <link
    name="base_link">
    <inertial>
      <origin
        xyz="-0.0057843 -0.00083393 -0.079813"
        rpy="0 0 0" />
      <mass
        value="2.9691" />
      <inertia
        ixx="0.02102"
        ixy="-9.4704E-06"
        ixz="-0.00083918"
        iyy="0.0097543"
        iyz="-5.5012E-05"
        izz="0.017836" />
    </inertial>
    <visual>
      <origin
        xyz="0 0 0"
        rpy="0 0 0" />
      <geometry>
        <mesh
          filename="package://robot_simulation/meshes/base_link.STL" />
      </geometry>
      <material
        name="">
        <color
          rgba="1 0 0 1" />
      </material>
    </visual>
    <collision>
      <origin
        xyz="0 0 0"
        rpy="0 0 0" />
      <geometry>
        <mesh
          filename="package://robot_simulation/meshes/base_link.STL" />
      </geometry>
    </collision>
  </link>
  <link
    name="s1">
    <inertial>
      <origin
        xyz="0.0097597 1.2918E-09 -0.027042"
        rpy="0 0 0" />
      <mass
        value="0.533877" />
      <inertia
        ixx="5.8446E-06"
        ixy="-1.5618E-13"
        ixz="2.7912E-07"
        iyy="9.573E-06"
        iyz="-6.4688E-13"
        izz="6.0162E-06" />
    </inertial>
    <visual>
      <origin
        xyz="0 0 0"
        rpy="0 0 3.14" />
      <geometry>
        <mesh
          filename="package://robot_simulation/meshes/s3.STL" />
      </geometry>
      <material
        name="">
        <color
          rgba="0.25098 0.25098 0.25098 1" />
      </material>
    </visual>
    <collision>
      <origin
        xyz="0 0 0"
        rpy="0 0 3.14" />
      <geometry>
        <mesh
          filename="package://robot_simulation/meshes/s3.STL" />
      </geometry>
    </collision>
  </link>
  <joint
    name="f1"
    type="fixed">
    <origin
      xyz="0.1138 -0.0025498 -0.0694"
      rpy="0 0 -1.5708" />
    <parent
      link="base_link" />
    <child
      link="s1" />
    <axis
      xyz="0 0 0" />
  </joint>
  <link
    name="l1">
    <inertial>
      <origin
        xyz="0.012916 -0.00012 0.00566"
        rpy="0 0 0" />
      <mass
        value="0.021604" />
      <inertia
        ixx="6.1894E-06"
        ixy="-2.0591E-08"
        ixz="-1.6049E-06"
        iyy="7.0947E-06"
        iyz="-2.5474E-07"
        izz="1.0286E-05" />
    </inertial>
    <visual>
      <origin
        xyz="0 0 0"
        rpy="0 0 0" />
      <geometry>
        <mesh
          filename="package://robot_simulation/meshes/l1.STL" />
      </geometry>
      <material
        name="">
        <color
          rgba="1 0 0 1" />
      </material>
    </visual>
    <collision>
      <origin
        xyz="0 0 0"
        rpy="0 0 0" />
      <geometry>
        <mesh
          filename="package://robot_simulation/meshes/l1.STL" />
      </geometry>
    </collision>
  </link>
  <joint
    name="j1"
    type="revolute">
    <origin
      xyz="0 0 0.003"
      rpy="0 0 -0.047093" />
    <parent
      link="s1" />
    <child
      link="l1" />
    <axis
      xyz="0 0 1" />
    <limit
      lower="-1.57"
      upper="1.57"
      effort="30"
      velocity="0.5" />
  </joint>
  <link
    name="s2">
    <inertial>
      <origin
        xyz="-0.0097597 -1.2984E-09 -0.027042"
        rpy="0 0 0" />
      <mass
        value="0.033877" />
      <inertia
        ixx="5.8446E-06"
        ixy="-1.5295E-13"
        ixz="-2.7912E-07"
        iyy="9.573E-06"
        iyz="6.4522E-13"
        izz="6.0162E-06" />
    </inertial>
    <visual>
      <origin
        xyz="0 0 0"
        rpy="0 0 0" />
      <geometry>
        <mesh
          filename="package://robot_simulation/meshes/s3.STL" />
      </geometry>
      <material
        name="">
        <color
          rgba="0.25098 0.25098 0.25098 1" />
      </material>
    </visual>
    <collision>
      <origin
        xyz="0 0 0"
        rpy="0 0 0" />
      <geometry>
        <mesh
          filename="package://robot_simulation/meshes/s3.STL" />
      </geometry>
    </collision>
  </link>
  <joint
    name="f2"
    type="fixed">
    <origin
      xyz="-0.0010939 0.00068914 0.03025"
      rpy="-1.5708 0 1.5708" />
    <parent
      link="l1" />
    <child
      link="s2" />
    <axis
      xyz="0 0 0" />
  </joint>
  <link
    name="l2">
    <inertial>
      <origin
        xyz="0.04379 -2.1528E-07 -0.0043754"
        rpy="0 0 0" />
      <mass
        value="0.034844" />
      <inertia
        ixx="5.0468E-06"
        ixy="5.1213E-11"
        ixz="6.0374E-07"
        iyy="5.3376E-05"
        iyz="-1.1889E-11"
        izz="5.7879E-05" />
    </inertial>
    <visual>
      <origin
        xyz="0 0 0"
        rpy="0 0 0" />
      <geometry>
        <mesh
          filename="package://robot_simulation/meshes/l2.STL" />
      </geometry>
      <material
        name="">
        <color
          rgba="1 0 0 1" />
      </material>
    </visual>
    <collision>
      <origin
        xyz="0 0 0"
        rpy="0 0 0" />
      <geometry>
        <mesh
          filename="package://robot_simulation/meshes/l2.STL" />
      </geometry>
    </collision>
  </link>
  <joint
    name="j2"
    type="revolute">
    <origin
      xyz="0 0 0.004"
      rpy="0 0 -0.026031" />
    <parent
      link="s2" />
    <child
      link="l2" />
    <axis
      xyz="0 0 1" />
    <limit
      lower="-2.20"
      upper="0.40"
      effort="30"
      velocity="0.5" />
  </joint>
  <link
    name="s3">
    <inertial>
      <origin
        xyz="-0.0097564 0.00025402 -0.027042"
        rpy="0 0 0" />
      <mass
        value="0.033877" />
      <inertia
        ixx="5.8471E-06"
        ixy="9.7009E-08"
        ixz="-2.7903E-07"
        iyy="9.5705E-06"
        iyz="7.2656E-09"
        izz="6.0162E-06" />
    </inertial>
    <visual>
      <origin
        xyz="0 0 0"
        rpy="0 0 0" />
      <geometry>
        <mesh
          filename="package://robot_simulation/meshes/s3.STL" />
      </geometry>
      <material
        name="">
        <color
          rgba="0.25098 0.25098 0.25098 1" />
      </material>
    </visual>
    <collision>
      <origin
        xyz="0 0 0"
        rpy="0 0 0" />
      <geometry>
        <mesh
          filename="package://robot_simulation/meshes/s3.STL" />
      </geometry>
    </collision>
  </link>
  <joint
    name="f3"
    type="fixed">
    <origin
      xyz="0.10075 -0.00025 0.0186"
      rpy="0 0 0.026031" />
    <parent
      link="l2" />
    <child
      link="s3" />
    <axis
      xyz="0 0 0" />
  </joint>
  <link
    name="l3">
    <inertial>
      <origin
        xyz="0.055011 -6.2859E-06 0.00010667"
        rpy="0 0 0" />
      <mass
        value="0.021877" />
      <inertia
        ixx="1.6912E-06"
        ixy="-3.0183E-09"
        ixz="5.0476E-08"
        iyy="3.1539E-05"
        iyz="4.5199E-10"
        izz="3.3088E-05" />
    </inertial>
    <visual>
      <origin
        xyz="0 0 0"
        rpy="0 0 0" />
      <geometry>
        <mesh
          filename="package://robot_simulation/meshes/l3.STL" />
      </geometry>
      <material
        name="">
        <color
          rgba="1 0 0 1" />
      </material>
    </visual>
    <collision>
      <origin
        xyz="0 0 0"
        rpy="0 0 0" />
      <geometry>
        <mesh
          filename="package://robot_simulation/meshes/l3.STL" />
      </geometry>
    </collision>
  </link>
  <joint
    name="j3"
    type="revolute">
    <origin
      xyz="0 0 0.003"
      rpy="0 0 -0.061183" />
    <parent
      link="s3" />
    <child
      link="l3" />
    <axis
      xyz="0 0 1" />
    <limit
      lower="-1.57"
      upper="1.57"
      effort="30"
      velocity="0.5" />
  </joint>
  <link
    name="s4">
    <inertial>
      <origin
        xyz="-0.0046716 9.423E-14 -0.017389"
        rpy="0 0 0" />
      <mass
        value="0.0071286" />
      <inertia
        ixx="4.5229E-07"
        ixy="3.4742E-23"
        ixz="-3.7047E-08"
        iyy="6.4894E-07"
        iyz="1.9232E-23"
        izz="3.7461E-07" />
    </inertial>
    <visual>
      <origin
        xyz="0 0 0"
        rpy="0 0 0" />
      <geometry>
        <mesh
          filename="package://robot_simulation/meshes/s4.STL" />
      </geometry>
      <material
        name="">
        <color
          rgba="0.12157 0.2549 1 1" />
      </material>
    </visual>
    <collision>
      <origin
        xyz="0 0 0"
        rpy="0 0 0" />
      <geometry>
        <mesh
          filename="package://robot_simulation/meshes/s4.STL" />
      </geometry>
    </collision>
  </link>
  <joint
    name="f4"
    type="fixed">
    <origin
      xyz="0.1108 0.0003 0.01725"
      rpy="0 0 0" />
    <parent
      link="l3" />
    <child
      link="s4" />
    <axis
      xyz="0 0 0" />
  </joint>
  <link
    name="l4">
    <inertial>
      <origin
        xyz="0.023551 -0.0058168 0.0019766"
        rpy="0 0 0" />
      <mass
        value="0.015721" />
      <inertia
        ixx="2.5605E-06"
        ixy="1.3641E-06"
        ixz="-1.4285E-06"
        iyy="8.1158E-06"
        iyz="3.5035E-07"
        izz="7.2474E-06" />
    </inertial>
    <visual>
      <origin
        xyz="0 0 0"
        rpy="0 0 0" />
      <geometry>
        <mesh
          filename="package://robot_simulation/meshes/l4.STL" />
      </geometry>
      <material
        name="">
        <color
          rgba="1 0 0 1" />
      </material>
    </visual>
    <collision>
      <origin
        xyz="0 0 0"
        rpy="0 0 0" />
      <geometry>
        <mesh
          filename="package://robot_simulation/meshes/l4.STL" />
      </geometry>
    </collision>
  </link>
  <joint
    name="j4"
    type="revolute">
    <origin
      xyz="0 0 0.005"
      rpy="0 0 0.24262" />
    <parent
      link="s4" />
    <child
      link="l4" />
    <axis
      xyz="0 0 1" />
    <limit
      lower="-1.57"
      upper="1.57"
      effort="30"
      velocity="0.5" />
  </joint>
<gazebo>
  <plugin name="gazebo_ros_control" filename="libgazebo_ros_control.so">
    <robotNamespace>/robot_simulation</robotNamespace>
    <robotSimType>gazebo_ros_control/DefaultRobotHWSim</robotSimType>
  </plugin>
</gazebo>

  <transmission name="tran1">
    <type>transmission_interface/SimpleTransmission</type>
    <joint name="j1">
      <hardwareInterface>hardware_interface/PositionJointInterface</hardwareInterface>
    </joint>
    <actuator name="m1">
      <hardwareInterface>PositionJointInterface</hardwareInterface>
      <mechanicalReduction>1</mechanicalReduction>
    </actuator>
  </transmission>
  <transmission name="tran2">
    <type>transmission_interface/SimpleTransmission</type>
    <joint name="j2">
      <hardwareInterface>hardware_interface/PositionJointInterface</hardwareInterface>
    </joint>
    <actuator name="m2">
      <hardwareInterface>PositionJointInterface</hardwareInterface>
      <mechanicalReduction>1</mechanicalReduction>
    </actuator>
  </transmission>
  <transmission name="tran3">
    <type>transmission_interface/SimpleTransmission</type>
    <joint name="j3">
      <hardwareInterface>hardware_interface/PositionJointInterface</hardwareInterface>
    </joint>
    <actuator name="m3">
      <hardwareInterface>PositionJointInterface</hardwareInterface>
      <mechanicalReduction>1</mechanicalReduction>
    </actuator>
  </transmission>
  <transmission name="tran4">
    <type>transmission_interface/SimpleTransmission</type>
    <joint name="j4">
      <hardwareInterface>hardware_interface/PositionJointInterface</hardwareInterface>
    </joint>
    <actuator name="m4">
      <hardwareInterface>PositionJointInterface</hardwareInterface>
      <mechanicalReduction>1</mechanicalReduction>
    </actuator>
  </transmission>

</robot>
